Lmod: loading gcc 8.5.0 
Lmod: loading python 3.10.10 
Lmod: loading cuda 11.8 
Lmod: loading cuDNN 8.8.1 
[W socket.cpp:426] [c10d] The server socket cannot be initialized on [::]:29500 (errno: 97 - Address family not supported by protocol).
[W socket.cpp:601] [c10d] The client socket cannot be initialized to connect to [localhost]:29500 (errno: 97 - Address family not supported by protocol).
[W socket.cpp:601] [c10d] The client socket cannot be initialized to connect to [localhost]:29500 (errno: 97 - Address family not supported by protocol).
wandb: Currently logged in as: bayer (few_shot). Use `wandb login --relogin` to force relogin
wandb: Currently logged in as: bayer (few_shot). Use `wandb login --relogin` to force relogin
wandb: Currently logged in as: bayer (few_shot). Use `wandb login --relogin` to force relogin
wandb: Currently logged in as: bayer (few_shot). Use `wandb login --relogin` to force relogin
wandb: Appending key for api.wandb.ai to your netrc file: /home/mb14sola/.netrc
wandb: Appending key for api.wandb.ai to your netrc file: /home/mb14sola/.netrc
wandb: Appending key for api.wandb.ai to your netrc file: /home/mb14sola/.netrc
wandb: Appending key for api.wandb.ai to your netrc file: /home/mb14sola/.netrc
Traceback (most recent call last):
  File "/work/projects/project02060/CyBERT/cybert/code/run_mlm.py", line 38, in <module>
    import transformers
ModuleNotFoundError: No module named 'transformers'
Traceback (most recent call last):
  File "/work/projects/project02060/CyBERT/cybert/code/run_mlm.py", line 38, in <module>
    import transformers
Traceback (most recent call last):
ModuleNotFoundError: No module named 'transformers'
  File "/work/projects/project02060/CyBERT/cybert/code/run_mlm.py", line 38, in <module>
    import transformers
ModuleNotFoundError: No module named 'transformers'
Traceback (most recent call last):
  File "/work/projects/project02060/CyBERT/cybert/code/run_mlm.py", line 38, in <module>
    import transformers
ModuleNotFoundError: No module named 'transformers'
ERROR:torch.distributed.elastic.multiprocessing.api:failed (exitcode: 1) local_rank: 0 (pid: 1607139) of binary: /shared/apps/.gcc/8.5/python/3.10.10/bin/python3.10
Traceback (most recent call last):
  File "/shared/apps/.gcc/8.5/python/3.10.10/bin/torchrun", line 8, in <module>
    sys.exit(main())
  File "/home/mb14sola/.local/lib/python3.10/site-packages/torch/distributed/elastic/multiprocessing/errors/__init__.py", line 346, in wrapper
    return f(*args, **kwargs)
  File "/home/mb14sola/.local/lib/python3.10/site-packages/torch/distributed/run.py", line 794, in main
    run(args)
  File "/home/mb14sola/.local/lib/python3.10/site-packages/torch/distributed/run.py", line 785, in run
    elastic_launch(
  File "/home/mb14sola/.local/lib/python3.10/site-packages/torch/distributed/launcher/api.py", line 134, in __call__
    return launch_agent(self._config, self._entrypoint, list(args))
  File "/home/mb14sola/.local/lib/python3.10/site-packages/torch/distributed/launcher/api.py", line 250, in launch_agent
    raise ChildFailedError(
torch.distributed.elastic.multiprocessing.errors.ChildFailedError: 
============================================================
cybert/code/run_mlm.py FAILED
------------------------------------------------------------
Failures:
[1]:
  time      : 2023-05-17_11:28:20
  host      : gaqc0001.lcluster
  rank      : 1 (local_rank: 1)
  exitcode  : 1 (pid: 1607140)
  error_file: <N/A>
  traceback : To enable traceback see: https://pytorch.org/docs/stable/elastic/errors.html
[2]:
  time      : 2023-05-17_11:28:20
  host      : gaqc0001.lcluster
  rank      : 2 (local_rank: 2)
  exitcode  : 1 (pid: 1607141)
  error_file: <N/A>
  traceback : To enable traceback see: https://pytorch.org/docs/stable/elastic/errors.html
[3]:
  time      : 2023-05-17_11:28:20
  host      : gaqc0001.lcluster
  rank      : 3 (local_rank: 3)
  exitcode  : 1 (pid: 1607142)
  error_file: <N/A>
  traceback : To enable traceback see: https://pytorch.org/docs/stable/elastic/errors.html
------------------------------------------------------------
Root Cause (first observed failure):
[0]:
  time      : 2023-05-17_11:28:20
  host      : gaqc0001.lcluster
  rank      : 0 (local_rank: 0)
  exitcode  : 1 (pid: 1607139)
  error_file: <N/A>
  traceback : To enable traceback see: https://pytorch.org/docs/stable/elastic/errors.html
============================================================
srun: error: gaqc0001: task 0: Exited with exit code 1
