Lmod: loading gcc 8.5.0 
Lmod: loading python 3.10.10 
Lmod: loading cuda 11.8 
Lmod: loading cuDNN 8.8.1 
/shared/apps/.gcc/8.5/python/3.10.10/lib/python3.10/site-packages/torch/distributed/launch.py:181: FutureWarning: The module torch.distributed.launch is deprecated
and will be removed in future. Use torchrun.
Note that --use-env is set by default in torchrun.
If your script expects `--local-rank` argument to be set, please
change it to read from `os.environ['LOCAL_RANK']` instead. See 
https://pytorch.org/docs/stable/distributed.html#launch-utility for 
further instructions

  warnings.warn(
/shared/apps/.gcc/8.5/python/3.10.10/lib/python3.10/site-packages/torch/distributed/launch.py:181: FutureWarning: The module torch.distributed.launch is deprecated
and will be removed in future. Use torchrun.
Note that --use-env is set by default in torchrun.
If your script expects `--local-rank` argument to be set, please
change it to read from `os.environ['LOCAL_RANK']` instead. See 
https://pytorch.org/docs/stable/distributed.html#launch-utility for 
further instructions

  warnings.warn(
/shared/apps/.gcc/8.5/python/3.10.10/lib/python3.10/site-packages/torch/distributed/launch.py:181: FutureWarning: The module torch.distributed.launch is deprecated
and will be removed in future. Use torchrun.
Note that --use-env is set by default in torchrun.
If your script expects `--local-rank` argument to be set, please
change it to read from `os.environ['LOCAL_RANK']` instead. See 
https://pytorch.org/docs/stable/distributed.html#launch-utility for 
further instructions

  warnings.warn(
/shared/apps/.gcc/8.5/python/3.10.10/lib/python3.10/site-packages/torch/distributed/launch.py:181: FutureWarning: The module torch.distributed.launch is deprecated
and will be removed in future. Use torchrun.
Note that --use-env is set by default in torchrun.
If your script expects `--local-rank` argument to be set, please
change it to read from `os.environ['LOCAL_RANK']` instead. See 
https://pytorch.org/docs/stable/distributed.html#launch-utility for 
further instructions

  warnings.warn(
[W socket.cpp:426] [c10d] The server socket cannot be initialized on [::]:29500 (errno: 97 - Address family not supported by protocol).
[W socket.cpp:426] [c10d] The server socket cannot be initialized on [::]:29500 (errno: 97 - Address family not supported by protocol).
[W socket.cpp:426] [c10d] The server socket cannot be initialized on [::]:29500 (errno: 97 - Address family not supported by protocol).
[W socket.cpp:601] [c10d] The client socket cannot be initialized to connect to [localhost]:29500 (errno: 97 - Address family not supported by protocol).
[W socket.cpp:601] [c10d] The client socket cannot be initialized to connect to [localhost]:29500 (errno: 97 - Address family not supported by protocol).
[W socket.cpp:426] [c10d] The server socket has failed to listen on 0.0.0.0:29500 (errno: 98 - Address already in use).
[E socket.cpp:462] [c10d] The server socket has failed to listen on any local network address.
[W socket.cpp:426] [c10d] The server socket has failed to bind to 0.0.0.0:29500 (errno: 98 - Address already in use).
[E socket.cpp:462] [c10d] The server socket has failed to listen on any local network address.
[W socket.cpp:426] [c10d] The server socket cannot be initialized on [::]:29500 (errno: 97 - Address family not supported by protocol).
[W socket.cpp:426] [c10d] The server socket has failed to bind to 0.0.0.0:29500 (errno: 98 - Address already in use).
[E socket.cpp:462] [c10d] The server socket has failed to listen on any local network address.
Traceback (most recent call last):
  File "/shared/apps/.gcc/8.5/python/3.10.10/lib/python3.10/runpy.py", line 196, in _run_module_as_main
Traceback (most recent call last):
  File "/shared/apps/.gcc/8.5/python/3.10.10/lib/python3.10/runpy.py", line 196, in _run_module_as_main
    return _run_code(code, main_globals, None,
  File "/shared/apps/.gcc/8.5/python/3.10.10/lib/python3.10/runpy.py", line 86, in _run_code
    return _run_code(code, main_globals, None,
  File "/shared/apps/.gcc/8.5/python/3.10.10/lib/python3.10/runpy.py", line 86, in _run_code
    exec(code, run_globals)
  File "/shared/apps/.gcc/8.5/python/3.10.10/lib/python3.10/site-packages/torch/distributed/launch.py", line 196, in <module>
    exec(code, run_globals)
  File "/shared/apps/.gcc/8.5/python/3.10.10/lib/python3.10/site-packages/torch/distributed/launch.py", line 196, in <module>
    main()
  File "/shared/apps/.gcc/8.5/python/3.10.10/lib/python3.10/site-packages/torch/distributed/launch.py", line 192, in main
    main()
  File "/shared/apps/.gcc/8.5/python/3.10.10/lib/python3.10/site-packages/torch/distributed/launch.py", line 192, in main
    launch(args)
  File "/shared/apps/.gcc/8.5/python/3.10.10/lib/python3.10/site-packages/torch/distributed/launch.py", line 177, in launch
    launch(args)
  File "/shared/apps/.gcc/8.5/python/3.10.10/lib/python3.10/site-packages/torch/distributed/launch.py", line 177, in launch
    run(args)
  File "/shared/apps/.gcc/8.5/python/3.10.10/lib/python3.10/site-packages/torch/distributed/run.py", line 785, in run
    run(args)
  File "/shared/apps/.gcc/8.5/python/3.10.10/lib/python3.10/site-packages/torch/distributed/run.py", line 785, in run
    elastic_launch(
  File "/shared/apps/.gcc/8.5/python/3.10.10/lib/python3.10/site-packages/torch/distributed/launcher/api.py", line 134, in __call__
    elastic_launch(
  File "/shared/apps/.gcc/8.5/python/3.10.10/lib/python3.10/site-packages/torch/distributed/launcher/api.py", line 134, in __call__
    return launch_agent(self._config, self._entrypoint, list(args))
  File "/shared/apps/.gcc/8.5/python/3.10.10/lib/python3.10/site-packages/torch/distributed/launcher/api.py", line 241, in launch_agent
    return launch_agent(self._config, self._entrypoint, list(args))
  File "/shared/apps/.gcc/8.5/python/3.10.10/lib/python3.10/site-packages/torch/distributed/launcher/api.py", line 241, in launch_agent
    result = agent.run()
  File "/shared/apps/.gcc/8.5/python/3.10.10/lib/python3.10/site-packages/torch/distributed/elastic/metrics/api.py", line 129, in wrapper
    result = f(*args, **kwargs)
  File "/shared/apps/.gcc/8.5/python/3.10.10/lib/python3.10/site-packages/torch/distributed/elastic/agent/server/api.py", line 723, in run
    result = agent.run()
  File "/shared/apps/.gcc/8.5/python/3.10.10/lib/python3.10/site-packages/torch/distributed/elastic/metrics/api.py", line 129, in wrapper
    result = f(*args, **kwargs)
  File "/shared/apps/.gcc/8.5/python/3.10.10/lib/python3.10/site-packages/torch/distributed/elastic/agent/server/api.py", line 723, in run
Traceback (most recent call last):
  File "/shared/apps/.gcc/8.5/python/3.10.10/lib/python3.10/runpy.py", line 196, in _run_module_as_main
    result = self._invoke_run(role)
  File "/shared/apps/.gcc/8.5/python/3.10.10/lib/python3.10/site-packages/torch/distributed/elastic/agent/server/api.py", line 858, in _invoke_run
    return _run_code(code, main_globals, None,
  File "/shared/apps/.gcc/8.5/python/3.10.10/lib/python3.10/runpy.py", line 86, in _run_code
    result = self._invoke_run(role)
  File "/shared/apps/.gcc/8.5/python/3.10.10/lib/python3.10/site-packages/torch/distributed/elastic/agent/server/api.py", line 858, in _invoke_run
    exec(code, run_globals)
  File "/shared/apps/.gcc/8.5/python/3.10.10/lib/python3.10/site-packages/torch/distributed/launch.py", line 196, in <module>
    self._initialize_workers(self._worker_group)
  File "/shared/apps/.gcc/8.5/python/3.10.10/lib/python3.10/site-packages/torch/distributed/elastic/metrics/api.py", line 129, in wrapper
    result = f(*args, **kwargs)
  File "/shared/apps/.gcc/8.5/python/3.10.10/lib/python3.10/site-packages/torch/distributed/elastic/agent/server/api.py", line 692, in _initialize_workers
    main()
  File "/shared/apps/.gcc/8.5/python/3.10.10/lib/python3.10/site-packages/torch/distributed/launch.py", line 192, in main
    self._initialize_workers(self._worker_group)
  File "/shared/apps/.gcc/8.5/python/3.10.10/lib/python3.10/site-packages/torch/distributed/elastic/metrics/api.py", line 129, in wrapper
    launch(args)
  File "/shared/apps/.gcc/8.5/python/3.10.10/lib/python3.10/site-packages/torch/distributed/launch.py", line 177, in launch
    self._rendezvous(worker_group)
  File "/shared/apps/.gcc/8.5/python/3.10.10/lib/python3.10/site-packages/torch/distributed/elastic/metrics/api.py", line 129, in wrapper
    result = f(*args, **kwargs)
  File "/shared/apps/.gcc/8.5/python/3.10.10/lib/python3.10/site-packages/torch/distributed/elastic/agent/server/api.py", line 692, in _initialize_workers
    result = f(*args, **kwargs)
  File "/shared/apps/.gcc/8.5/python/3.10.10/lib/python3.10/site-packages/torch/distributed/elastic/agent/server/api.py", line 546, in _rendezvous
    run(args)
  File "/shared/apps/.gcc/8.5/python/3.10.10/lib/python3.10/site-packages/torch/distributed/run.py", line 785, in run
    self._rendezvous(worker_group)
  File "/shared/apps/.gcc/8.5/python/3.10.10/lib/python3.10/site-packages/torch/distributed/elastic/metrics/api.py", line 129, in wrapper
    store, group_rank, group_world_size = spec.rdzv_handler.next_rendezvous()
  File "/shared/apps/.gcc/8.5/python/3.10.10/lib/python3.10/site-packages/torch/distributed/elastic/rendezvous/static_tcp_rendezvous.py", line 55, in next_rendezvous
    result = f(*args, **kwargs)
  File "/shared/apps/.gcc/8.5/python/3.10.10/lib/python3.10/site-packages/torch/distributed/elastic/agent/server/api.py", line 546, in _rendezvous
    self._store = TCPStore(  # type: ignore[call-arg]
RuntimeError: The server socket has failed to listen on any local network address. The server socket cannot be initialized on [::]:29500 (errno: 97 - Address family not supported by protocol). The server socket has failed to bind to 0.0.0.0:29500 (errno: 98 - Address already in use).
    elastic_launch(
  File "/shared/apps/.gcc/8.5/python/3.10.10/lib/python3.10/site-packages/torch/distributed/launcher/api.py", line 134, in __call__
    store, group_rank, group_world_size = spec.rdzv_handler.next_rendezvous()
  File "/shared/apps/.gcc/8.5/python/3.10.10/lib/python3.10/site-packages/torch/distributed/elastic/rendezvous/static_tcp_rendezvous.py", line 55, in next_rendezvous
    return launch_agent(self._config, self._entrypoint, list(args))
  File "/shared/apps/.gcc/8.5/python/3.10.10/lib/python3.10/site-packages/torch/distributed/launcher/api.py", line 241, in launch_agent
    self._store = TCPStore(  # type: ignore[call-arg]
RuntimeError: The server socket has failed to listen on any local network address. The server socket cannot be initialized on [::]:29500 (errno: 97 - Address family not supported by protocol). The server socket has failed to listen on 0.0.0.0:29500 (errno: 98 - Address already in use).
    result = agent.run()
  File "/shared/apps/.gcc/8.5/python/3.10.10/lib/python3.10/site-packages/torch/distributed/elastic/metrics/api.py", line 129, in wrapper
    result = f(*args, **kwargs)
  File "/shared/apps/.gcc/8.5/python/3.10.10/lib/python3.10/site-packages/torch/distributed/elastic/agent/server/api.py", line 723, in run
    result = self._invoke_run(role)
  File "/shared/apps/.gcc/8.5/python/3.10.10/lib/python3.10/site-packages/torch/distributed/elastic/agent/server/api.py", line 858, in _invoke_run
    self._initialize_workers(self._worker_group)
  File "/shared/apps/.gcc/8.5/python/3.10.10/lib/python3.10/site-packages/torch/distributed/elastic/metrics/api.py", line 129, in wrapper
    result = f(*args, **kwargs)
  File "/shared/apps/.gcc/8.5/python/3.10.10/lib/python3.10/site-packages/torch/distributed/elastic/agent/server/api.py", line 692, in _initialize_workers
    self._rendezvous(worker_group)
  File "/shared/apps/.gcc/8.5/python/3.10.10/lib/python3.10/site-packages/torch/distributed/elastic/metrics/api.py", line 129, in wrapper
    result = f(*args, **kwargs)
  File "/shared/apps/.gcc/8.5/python/3.10.10/lib/python3.10/site-packages/torch/distributed/elastic/agent/server/api.py", line 546, in _rendezvous
    store, group_rank, group_world_size = spec.rdzv_handler.next_rendezvous()
  File "/shared/apps/.gcc/8.5/python/3.10.10/lib/python3.10/site-packages/torch/distributed/elastic/rendezvous/static_tcp_rendezvous.py", line 55, in next_rendezvous
    self._store = TCPStore(  # type: ignore[call-arg]
RuntimeError: The server socket has failed to listen on any local network address. The server socket cannot be initialized on [::]:29500 (errno: 97 - Address family not supported by protocol). The server socket has failed to bind to 0.0.0.0:29500 (errno: 98 - Address already in use).
srun: error: gvqc0001: tasks 0,2-3: Exited with exit code 1
wandb: Currently logged in as: bayer (few_shot). Use `wandb login --relogin` to force relogin
wandb: Appending key for api.wandb.ai to your netrc file: /home/mb14sola/.netrc
wandb: Currently logged in as: bayer (few_shot). Use `wandb login --relogin` to force relogin
wandb: Currently logged in as: bayer (few_shot). Use `wandb login --relogin` to force relogin
wandb: Appending key for api.wandb.ai to your netrc file: /home/mb14sola/.netrc
wandb: Appending key for api.wandb.ai to your netrc file: /home/mb14sola/.netrc
wandb: Currently logged in as: bayer (few_shot). Use `wandb login --relogin` to force relogin
wandb: Appending key for api.wandb.ai to your netrc file: /home/mb14sola/.netrc
Traceback (most recent call last):
  File "/work/projects/project02060/CyBERT/cybert/code/run_mlm.py", line 38, in <module>
    import transformers
Traceback (most recent call last):
ModuleNotFoundError: No module named 'transformers'
  File "/work/projects/project02060/CyBERT/cybert/code/run_mlm.py", line 38, in <module>
    import transformers
ModuleNotFoundError: No module named 'transformers'
Traceback (most recent call last):
Traceback (most recent call last):
  File "/work/projects/project02060/CyBERT/cybert/code/run_mlm.py", line 38, in <module>
    import transformers
  File "/work/projects/project02060/CyBERT/cybert/code/run_mlm.py", line 38, in <module>
    import transformers
ModuleNotFoundError: No module named 'transformers'
ModuleNotFoundError: No module named 'transformers'
ERROR:torch.distributed.elastic.multiprocessing.api:failed (exitcode: 1) local_rank: 0 (pid: 538296) of binary: /shared/apps/.gcc/8.5/python/3.10.10/bin/python
Traceback (most recent call last):
  File "/shared/apps/.gcc/8.5/python/3.10.10/lib/python3.10/runpy.py", line 196, in _run_module_as_main
    return _run_code(code, main_globals, None,
  File "/shared/apps/.gcc/8.5/python/3.10.10/lib/python3.10/runpy.py", line 86, in _run_code
    exec(code, run_globals)
  File "/shared/apps/.gcc/8.5/python/3.10.10/lib/python3.10/site-packages/torch/distributed/launch.py", line 196, in <module>
    main()
  File "/shared/apps/.gcc/8.5/python/3.10.10/lib/python3.10/site-packages/torch/distributed/launch.py", line 192, in main
    launch(args)
  File "/shared/apps/.gcc/8.5/python/3.10.10/lib/python3.10/site-packages/torch/distributed/launch.py", line 177, in launch
    run(args)
  File "/shared/apps/.gcc/8.5/python/3.10.10/lib/python3.10/site-packages/torch/distributed/run.py", line 785, in run
    elastic_launch(
  File "/shared/apps/.gcc/8.5/python/3.10.10/lib/python3.10/site-packages/torch/distributed/launcher/api.py", line 134, in __call__
    return launch_agent(self._config, self._entrypoint, list(args))
  File "/shared/apps/.gcc/8.5/python/3.10.10/lib/python3.10/site-packages/torch/distributed/launcher/api.py", line 250, in launch_agent
    raise ChildFailedError(
torch.distributed.elastic.multiprocessing.errors.ChildFailedError: 
============================================================
cybert/code/run_mlm.py FAILED
------------------------------------------------------------
Failures:
[1]:
  time      : 2023-04-13_08:46:00
  host      : gvqc0001.lcluster
  rank      : 1 (local_rank: 1)
  exitcode  : 1 (pid: 538297)
  error_file: <N/A>
  traceback : To enable traceback see: https://pytorch.org/docs/stable/elastic/errors.html
[2]:
  time      : 2023-04-13_08:46:00
  host      : gvqc0001.lcluster
  rank      : 2 (local_rank: 2)
  exitcode  : 1 (pid: 538298)
  error_file: <N/A>
  traceback : To enable traceback see: https://pytorch.org/docs/stable/elastic/errors.html
[3]:
  time      : 2023-04-13_08:46:00
  host      : gvqc0001.lcluster
  rank      : 3 (local_rank: 3)
  exitcode  : 1 (pid: 538299)
  error_file: <N/A>
  traceback : To enable traceback see: https://pytorch.org/docs/stable/elastic/errors.html
------------------------------------------------------------
Root Cause (first observed failure):
[0]:
  time      : 2023-04-13_08:46:00
  host      : gvqc0001.lcluster
  rank      : 0 (local_rank: 0)
  exitcode  : 1 (pid: 538296)
  error_file: <N/A>
  traceback : To enable traceback see: https://pytorch.org/docs/stable/elastic/errors.html
============================================================
srun: error: gvqc0001: task 1: Exited with exit code 1
